[2024-07-03T22:04:40.065+0000] {local_task_job_runner.py:120} INFO - ::group::Pre task execution logs
[2024-07-03T22:04:40.127+0000] {taskinstance.py:2076} INFO - Dependencies all met for dep_context=non-requeueable deps ti=<TaskInstance: exchange_rate_dag.run_script scheduled__2024-02-18T00:00:00+00:00 [queued]>
[2024-07-03T22:04:40.143+0000] {taskinstance.py:2076} INFO - Dependencies all met for dep_context=requeueable deps ti=<TaskInstance: exchange_rate_dag.run_script scheduled__2024-02-18T00:00:00+00:00 [queued]>
[2024-07-03T22:04:40.259+0000] {taskinstance.py:2306} INFO - Starting attempt 1 of 2
[2024-07-03T22:04:40.348+0000] {taskinstance.py:2330} INFO - Executing <Task(PythonOperator): run_script> on 2024-02-18 00:00:00+00:00
[2024-07-03T22:04:40.386+0000] {warnings.py:112} WARNING - /home/***/.local/lib/python3.12/site-packages/***/task/task_runner/standard_task_runner.py:61: DeprecationWarning: This process (pid=115) is multi-threaded, use of fork() may lead to deadlocks in the child.
  pid = os.fork()

[2024-07-03T22:04:40.403+0000] {standard_task_runner.py:63} INFO - Started process 129 to run task
[2024-07-03T22:04:40.399+0000] {standard_task_runner.py:90} INFO - Running: ['***', 'tasks', 'run', 'exchange_rate_dag', 'run_script', 'scheduled__2024-02-18T00:00:00+00:00', '--job-id', '98', '--raw', '--subdir', 'DAGS_FOLDER/my_dag.py', '--cfg-path', '/tmp/tmppgcnkknu']
[2024-07-03T22:04:40.427+0000] {standard_task_runner.py:91} INFO - Job 98: Subtask run_script
[2024-07-03T22:04:40.725+0000] {task_command.py:426} INFO - Running <TaskInstance: exchange_rate_dag.run_script scheduled__2024-02-18T00:00:00+00:00 [running]> on host bab0a72648e8
[2024-07-03T22:04:41.445+0000] {taskinstance.py:2648} INFO - Exporting env vars: AIRFLOW_CTX_DAG_OWNER='juan_ml' AIRFLOW_CTX_DAG_ID='exchange_rate_dag' AIRFLOW_CTX_TASK_ID='run_script' AIRFLOW_CTX_EXECUTION_DATE='2024-02-18T00:00:00+00:00' AIRFLOW_CTX_TRY_NUMBER='1' AIRFLOW_CTX_DAG_RUN_ID='scheduled__2024-02-18T00:00:00+00:00'
[2024-07-03T22:04:41.459+0000] {taskinstance.py:430} INFO - ::endgroup::
[2024-07-03T22:04:41.461+0000] {logging_mixin.py:188} INFO - All credentials are set properly.
[2024-07-03T22:04:41.462+0000] {logging_mixin.py:188} INFO - Error al crear la tabla en Redshift: invalid literal for int() with base 10: 'None'
[2024-07-03T22:04:42.145+0000] {logging_mixin.py:188} INFO - Error al realizar la solicitud a la API: 401 Client Error: Unauthorized for url: https://api.apilayer.com/exchangerates_data/latest?symbols=EUR,USD,CNY&base=ARS
[2024-07-03T22:04:42.158+0000] {python.py:237} INFO - Done. Returned value was: None
[2024-07-03T22:04:42.164+0000] {taskinstance.py:441} INFO - ::group::Post task execution logs
[2024-07-03T22:04:42.216+0000] {taskinstance.py:1206} INFO - Marking task as SUCCESS. dag_id=exchange_rate_dag, task_id=run_script, run_id=scheduled__2024-02-18T00:00:00+00:00, execution_date=20240218T000000, start_date=20240703T220440, end_date=20240703T220442
[2024-07-03T22:04:42.356+0000] {local_task_job_runner.py:240} INFO - Task exited with return code 0
[2024-07-03T22:04:42.420+0000] {local_task_job_runner.py:222} INFO - ::endgroup::
[2024-07-03T22:48:32.437+0000] {local_task_job_runner.py:120} INFO - ::group::Pre task execution logs
[2024-07-03T22:48:32.579+0000] {taskinstance.py:2076} INFO - Dependencies all met for dep_context=non-requeueable deps ti=<TaskInstance: exchange_rate_dag.run_script scheduled__2024-02-18T00:00:00+00:00 [queued]>
[2024-07-03T22:48:32.610+0000] {taskinstance.py:2076} INFO - Dependencies all met for dep_context=requeueable deps ti=<TaskInstance: exchange_rate_dag.run_script scheduled__2024-02-18T00:00:00+00:00 [queued]>
[2024-07-03T22:48:32.612+0000] {taskinstance.py:2306} INFO - Starting attempt 1 of 2
[2024-07-03T22:48:33.077+0000] {taskinstance.py:2330} INFO - Executing <Task(PythonOperator): run_script> on 2024-02-18 00:00:00+00:00
[2024-07-03T22:48:33.395+0000] {warnings.py:112} WARNING - /home/***/.local/lib/python3.12/site-packages/***/task/task_runner/standard_task_runner.py:61: DeprecationWarning: This process (pid=126) is multi-threaded, use of fork() may lead to deadlocks in the child.
  pid = os.fork()

[2024-07-03T22:48:33.399+0000] {standard_task_runner.py:90} INFO - Running: ['***', 'tasks', 'run', 'exchange_rate_dag', 'run_script', 'scheduled__2024-02-18T00:00:00+00:00', '--job-id', '20', '--raw', '--subdir', 'DAGS_FOLDER/my_dag.py', '--cfg-path', '/tmp/tmpqors15gs']
[2024-07-03T22:48:33.533+0000] {standard_task_runner.py:63} INFO - Started process 142 to run task
[2024-07-03T22:48:33.534+0000] {standard_task_runner.py:91} INFO - Job 20: Subtask run_script
[2024-07-03T22:48:34.332+0000] {task_command.py:426} INFO - Running <TaskInstance: exchange_rate_dag.run_script scheduled__2024-02-18T00:00:00+00:00 [running]> on host 0b7358cba041
[2024-07-03T22:48:36.246+0000] {taskinstance.py:2648} INFO - Exporting env vars: AIRFLOW_CTX_DAG_OWNER='juan_ml' AIRFLOW_CTX_DAG_ID='exchange_rate_dag' AIRFLOW_CTX_TASK_ID='run_script' AIRFLOW_CTX_EXECUTION_DATE='2024-02-18T00:00:00+00:00' AIRFLOW_CTX_TRY_NUMBER='1' AIRFLOW_CTX_DAG_RUN_ID='scheduled__2024-02-18T00:00:00+00:00'
[2024-07-03T22:48:36.251+0000] {taskinstance.py:430} INFO - ::endgroup::
[2024-07-03T22:48:36.253+0000] {logging_mixin.py:188} INFO - All credentials are set properly.
[2024-07-03T22:48:36.255+0000] {logging_mixin.py:188} INFO - Error al crear la tabla en Redshift: invalid literal for int() with base 10: 'None'
[2024-07-03T22:48:46.279+0000] {logging_mixin.py:188} INFO - Error al realizar la solicitud a la API: HTTPSConnectionPool(host='api.apilayer.com', port=443): Max retries exceeded with url: /exchangerates_data/latest?symbols=EUR,USD,CNY&base=ARS (Caused by NameResolutionError("<urllib3.connection.HTTPSConnection object at 0x7f7c8e29f2c0>: Failed to resolve 'api.apilayer.com' ([Errno -3] Temporary failure in name resolution)"))
[2024-07-03T22:48:46.431+0000] {python.py:237} INFO - Done. Returned value was: None
[2024-07-03T22:48:46.432+0000] {taskinstance.py:441} INFO - ::group::Post task execution logs
[2024-07-03T22:49:25.639+0000] {job.py:218} ERROR - Job heartbeat got an exception
Traceback (most recent call last):
  File "/home/airflow/.local/lib/python3.12/site-packages/sqlalchemy/engine/base.py", line 3371, in _wrap_pool_connect
    return fn()
           ^^^^
  File "/home/airflow/.local/lib/python3.12/site-packages/sqlalchemy/pool/base.py", line 327, in connect
    return _ConnectionFairy._checkout(self)
           ^^^^^^^^^^^^^^^^^^^^^^^^^^^^^^^^
  File "/home/airflow/.local/lib/python3.12/site-packages/sqlalchemy/pool/base.py", line 894, in _checkout
    fairy = _ConnectionRecord.checkout(pool)
            ^^^^^^^^^^^^^^^^^^^^^^^^^^^^^^^^
  File "/home/airflow/.local/lib/python3.12/site-packages/sqlalchemy/pool/base.py", line 493, in checkout
    rec = pool._do_get()
          ^^^^^^^^^^^^^^
  File "/home/airflow/.local/lib/python3.12/site-packages/sqlalchemy/pool/impl.py", line 256, in _do_get
    return self._create_connection()
           ^^^^^^^^^^^^^^^^^^^^^^^^^
  File "/home/airflow/.local/lib/python3.12/site-packages/sqlalchemy/pool/base.py", line 273, in _create_connection
    return _ConnectionRecord(self)
           ^^^^^^^^^^^^^^^^^^^^^^^
  File "/home/airflow/.local/lib/python3.12/site-packages/sqlalchemy/pool/base.py", line 388, in __init__
    self.__connect()
  File "/home/airflow/.local/lib/python3.12/site-packages/sqlalchemy/pool/base.py", line 690, in __connect
    with util.safe_reraise():
  File "/home/airflow/.local/lib/python3.12/site-packages/sqlalchemy/util/langhelpers.py", line 70, in __exit__
    compat.raise_(
  File "/home/airflow/.local/lib/python3.12/site-packages/sqlalchemy/util/compat.py", line 211, in raise_
    raise exception
  File "/home/airflow/.local/lib/python3.12/site-packages/sqlalchemy/pool/base.py", line 686, in __connect
    self.dbapi_connection = connection = pool._invoke_creator(self)
                                         ^^^^^^^^^^^^^^^^^^^^^^^^^^
  File "/home/airflow/.local/lib/python3.12/site-packages/sqlalchemy/engine/create.py", line 574, in connect
    return dialect.connect(*cargs, **cparams)
           ^^^^^^^^^^^^^^^^^^^^^^^^^^^^^^^^^^
  File "/home/airflow/.local/lib/python3.12/site-packages/sqlalchemy/engine/default.py", line 598, in connect
    return self.dbapi.connect(*cargs, **cparams)
           ^^^^^^^^^^^^^^^^^^^^^^^^^^^^^^^^^^^^^
  File "/home/airflow/.local/lib/python3.12/site-packages/psycopg2/__init__.py", line 122, in connect
    conn = _connect(dsn, connection_factory=connection_factory, **kwasync)
           ^^^^^^^^^^^^^^^^^^^^^^^^^^^^^^^^^^^^^^^^^^^^^^^^^^^^^^^^^^^^^^^
psycopg2.OperationalError: could not translate host name "postgres" to address: Temporary failure in name resolution


The above exception was the direct cause of the following exception:

Traceback (most recent call last):
  File "/home/airflow/.local/lib/python3.12/site-packages/airflow/jobs/job.py", line 192, in heartbeat
    self._merge_from(Job._fetch_from_db(self, session))
                     ^^^^^^^^^^^^^^^^^^^^^^^^^^^^^^^^^
  File "/home/airflow/.local/lib/python3.12/site-packages/airflow/api_internal/internal_api_call.py", line 115, in wrapper
    return func(*args, **kwargs)
           ^^^^^^^^^^^^^^^^^^^^^
  File "/home/airflow/.local/lib/python3.12/site-packages/airflow/utils/session.py", line 76, in wrapper
    return func(*args, **kwargs)
           ^^^^^^^^^^^^^^^^^^^^^
  File "/home/airflow/.local/lib/python3.12/site-packages/airflow/utils/retries.py", line 89, in wrapped_function
    for attempt in run_with_db_retries(max_retries=retries, logger=logger, **retry_kwargs):
  File "/home/airflow/.local/lib/python3.12/site-packages/tenacity/__init__.py", line 435, in __iter__
    do = self.iter(retry_state=retry_state)
         ^^^^^^^^^^^^^^^^^^^^^^^^^^^^^^^^^^
  File "/home/airflow/.local/lib/python3.12/site-packages/tenacity/__init__.py", line 368, in iter
    result = action(retry_state)
             ^^^^^^^^^^^^^^^^^^^
  File "/home/airflow/.local/lib/python3.12/site-packages/tenacity/__init__.py", line 410, in exc_check
    raise retry_exc.reraise()
          ^^^^^^^^^^^^^^^^^^^
  File "/home/airflow/.local/lib/python3.12/site-packages/tenacity/__init__.py", line 183, in reraise
    raise self.last_attempt.result()
          ^^^^^^^^^^^^^^^^^^^^^^^^^^
  File "/usr/local/lib/python3.12/concurrent/futures/_base.py", line 449, in result
    return self.__get_result()
           ^^^^^^^^^^^^^^^^^^^
  File "/usr/local/lib/python3.12/concurrent/futures/_base.py", line 401, in __get_result
    raise self._exception
  File "/home/airflow/.local/lib/python3.12/site-packages/airflow/utils/retries.py", line 98, in wrapped_function
    return func(*args, **kwargs)
           ^^^^^^^^^^^^^^^^^^^^^
  File "/home/airflow/.local/lib/python3.12/site-packages/airflow/jobs/job.py", line 316, in _fetch_from_db
    session.merge(job)
  File "/home/airflow/.local/lib/python3.12/site-packages/sqlalchemy/orm/session.py", line 3056, in merge
    return self._merge(
           ^^^^^^^^^^^^
  File "/home/airflow/.local/lib/python3.12/site-packages/sqlalchemy/orm/session.py", line 3136, in _merge
    merged = self.get(
             ^^^^^^^^^
  File "/home/airflow/.local/lib/python3.12/site-packages/sqlalchemy/orm/session.py", line 2853, in get
    return self._get_impl(
           ^^^^^^^^^^^^^^^
  File "/home/airflow/.local/lib/python3.12/site-packages/sqlalchemy/orm/session.py", line 2975, in _get_impl
    return db_load_fn(
           ^^^^^^^^^^^
  File "/home/airflow/.local/lib/python3.12/site-packages/sqlalchemy/orm/loading.py", line 530, in load_on_pk_identity
    session.execute(
  File "/home/airflow/.local/lib/python3.12/site-packages/sqlalchemy/orm/session.py", line 1716, in execute
    conn = self._connection_for_bind(bind)
           ^^^^^^^^^^^^^^^^^^^^^^^^^^^^^^^
  File "/home/airflow/.local/lib/python3.12/site-packages/sqlalchemy/orm/session.py", line 1555, in _connection_for_bind
    return self._transaction._connection_for_bind(
           ^^^^^^^^^^^^^^^^^^^^^^^^^^^^^^^^^^^^^^^
  File "/home/airflow/.local/lib/python3.12/site-packages/sqlalchemy/orm/session.py", line 750, in _connection_for_bind
    conn = bind.connect()
           ^^^^^^^^^^^^^^
  File "/home/airflow/.local/lib/python3.12/site-packages/sqlalchemy/future/engine.py", line 412, in connect
    return super(Engine, self).connect()
           ^^^^^^^^^^^^^^^^^^^^^^^^^^^^^
  File "/home/airflow/.local/lib/python3.12/site-packages/sqlalchemy/engine/base.py", line 3325, in connect
    return self._connection_cls(self, close_with_result=close_with_result)
           ^^^^^^^^^^^^^^^^^^^^^^^^^^^^^^^^^^^^^^^^^^^^^^^^^^^^^^^^^^^^^^^
  File "/home/airflow/.local/lib/python3.12/site-packages/sqlalchemy/engine/base.py", line 96, in __init__
    else engine.raw_connection()
         ^^^^^^^^^^^^^^^^^^^^^^^
  File "/home/airflow/.local/lib/python3.12/site-packages/sqlalchemy/engine/base.py", line 3404, in raw_connection
    return self._wrap_pool_connect(self.pool.connect, _connection)
           ^^^^^^^^^^^^^^^^^^^^^^^^^^^^^^^^^^^^^^^^^^^^^^^^^^^^^^^
  File "/home/airflow/.local/lib/python3.12/site-packages/sqlalchemy/engine/base.py", line 3374, in _wrap_pool_connect
    Connection._handle_dbapi_exception_noconnection(
  File "/home/airflow/.local/lib/python3.12/site-packages/sqlalchemy/engine/base.py", line 2208, in _handle_dbapi_exception_noconnection
    util.raise_(
  File "/home/airflow/.local/lib/python3.12/site-packages/sqlalchemy/util/compat.py", line 211, in raise_
    raise exception
  File "/home/airflow/.local/lib/python3.12/site-packages/sqlalchemy/engine/base.py", line 3371, in _wrap_pool_connect
    return fn()
           ^^^^
  File "/home/airflow/.local/lib/python3.12/site-packages/sqlalchemy/pool/base.py", line 327, in connect
    return _ConnectionFairy._checkout(self)
           ^^^^^^^^^^^^^^^^^^^^^^^^^^^^^^^^
  File "/home/airflow/.local/lib/python3.12/site-packages/sqlalchemy/pool/base.py", line 894, in _checkout
    fairy = _ConnectionRecord.checkout(pool)
            ^^^^^^^^^^^^^^^^^^^^^^^^^^^^^^^^
  File "/home/airflow/.local/lib/python3.12/site-packages/sqlalchemy/pool/base.py", line 493, in checkout
    rec = pool._do_get()
          ^^^^^^^^^^^^^^
  File "/home/airflow/.local/lib/python3.12/site-packages/sqlalchemy/pool/impl.py", line 256, in _do_get
    return self._create_connection()
           ^^^^^^^^^^^^^^^^^^^^^^^^^
  File "/home/airflow/.local/lib/python3.12/site-packages/sqlalchemy/pool/base.py", line 273, in _create_connection
    return _ConnectionRecord(self)
           ^^^^^^^^^^^^^^^^^^^^^^^
  File "/home/airflow/.local/lib/python3.12/site-packages/sqlalchemy/pool/base.py", line 388, in __init__
    self.__connect()
  File "/home/airflow/.local/lib/python3.12/site-packages/sqlalchemy/pool/base.py", line 690, in __connect
    with util.safe_reraise():
  File "/home/airflow/.local/lib/python3.12/site-packages/sqlalchemy/util/langhelpers.py", line 70, in __exit__
    compat.raise_(
  File "/home/airflow/.local/lib/python3.12/site-packages/sqlalchemy/util/compat.py", line 211, in raise_
    raise exception
  File "/home/airflow/.local/lib/python3.12/site-packages/sqlalchemy/pool/base.py", line 686, in __connect
    self.dbapi_connection = connection = pool._invoke_creator(self)
                                         ^^^^^^^^^^^^^^^^^^^^^^^^^^
  File "/home/airflow/.local/lib/python3.12/site-packages/sqlalchemy/engine/create.py", line 574, in connect
    return dialect.connect(*cargs, **cparams)
           ^^^^^^^^^^^^^^^^^^^^^^^^^^^^^^^^^^
  File "/home/airflow/.local/lib/python3.12/site-packages/sqlalchemy/engine/default.py", line 598, in connect
    return self.dbapi.connect(*cargs, **cparams)
           ^^^^^^^^^^^^^^^^^^^^^^^^^^^^^^^^^^^^^
  File "/home/airflow/.local/lib/python3.12/site-packages/psycopg2/__init__.py", line 122, in connect
    conn = _connect(dsn, connection_factory=connection_factory, **kwasync)
           ^^^^^^^^^^^^^^^^^^^^^^^^^^^^^^^^^^^^^^^^^^^^^^^^^^^^^^^^^^^^^^^
sqlalchemy.exc.OperationalError: (psycopg2.OperationalError) could not translate host name "postgres" to address: Temporary failure in name resolution

(Background on this error at: https://sqlalche.me/e/14/e3q8)
[2024-07-03T22:49:30.712+0000] {job.py:226} ERROR - Job heartbeat failed with error. Scheduler is in unhealthy state
[2024-07-03T22:49:33.458+0000] {taskinstance.py:1206} INFO - Marking task as SUCCESS. dag_id=exchange_rate_dag, task_id=run_script, run_id=scheduled__2024-02-18T00:00:00+00:00, execution_date=20240218T000000, start_date=20240703T224832, end_date=20240703T224933
[2024-07-03T22:49:33.904+0000] {local_task_job_runner.py:240} INFO - Task exited with return code 0
[2024-07-03T22:49:34.229+0000] {taskinstance.py:3503} INFO - 0 downstream tasks scheduled from follow-on schedule check
[2024-07-03T22:49:34.264+0000] {local_task_job_runner.py:222} INFO - ::endgroup::
